<?xml version="1.0" ?>
<!-- =================================================================================== -->
<!-- |    This document was autogenerated by xacro from dc_left_xacro.xacro            | -->
<!-- |    EDITING THIS FILE BY HAND IS NOT RECOMMENDED                                 | -->
<!-- =================================================================================== -->
<robot name="minesweeper_left">
  <link name="base_link"/>
  <link name="circular_plate_link">
    <visual>
      <geometry>
        <cylinder length="0.0025" radius="0.03"/>
      </geometry>
      <origin rpy="1.5707963267948966 0 0" xyz="0 0 0"/>
    </visual>
  </link>
  <joint name="circular_plate_joint" type="fixed">
    <parent link="base_link"/>
    <child link="circular_plate_link"/>
  </joint>
  <link name="bracket_link">
    <visual>
      <geometry>
        <cylinder length="0.06" radius="0.02"/>
      </geometry>
      <origin rpy="0 0 0" xyz="0 0 0"/>
    </visual>
  </link>
  <joint name="bracket_joint" type="fixed">
    <parent link="base_link"/>
    <child link="bracket_link"/>
    <origin rpy="1.5707963267948966 0 0" xyz="0 0.03125 0"/>
  </joint>
  <link name="rot_bracket_link">
    <visual>
      <geometry>
        <cylinder length="0.04" radius="0.03"/>
      </geometry>
      <origin rpy="0 0 0" xyz="0 0 0"/>
    </visual>
    <visual>
      <geometry>
        <box size="0.05 0.04 0.04"/>
      </geometry>
      <origin rpy="0 0 -0.5235987755982988" xyz="0.025 -0.02 0"/>
    </visual>
    <visual>
      <geometry>
        <box size="0.05 0.04 0.04"/>
      </geometry>
      <origin rpy="0 0 0.5235987755982988" xyz="-0.025 -0.02 0"/>
    </visual>
  </link>
  <joint name="rot_bracket_joint" type="fixed">
    <parent link="bracket_link"/>
    <child link="rot_bracket_link"/>
    <origin rpy="0 0 0" xyz="0 0 -0.05"/>
  </joint>
  <link name="metal_leg_link">
    <visual>
      <geometry>
        <box size="0.164 0.0218 0.0218"/>
      </geometry>
      <origin rpy="0 0 0" xyz="0 0 0"/>
      <material name="steel">
        <color rgba="0.5 0.5 0.5 1"/>
        <!-- Adjust the RGBA values for your desired color and opacity -->
      </material>
    </visual>
  </link>
  <joint name="metal_leg_joint" type="fixed">
    <parent link="rot_bracket_link"/>
    <child link="metal_leg_link"/>
    <origin rpy="0 0 -0.5235987755982988" xyz="0.11864200000000001 -0.0685 0"/>
  </joint>
  <link name="metal_leg_mirror_link">
    <visual>
      <geometry>
        <box size="0.08 0.0218 0.0218"/>
      </geometry>
      <origin rpy="0 0 0" xyz="0 0 0"/>
      <material name="steel">
        <color rgba="0.5 0.5 0.5 1"/>
        <!-- Adjust the RGBA values for your desired color and opacity -->
      </material>
    </visual>
  </link>
  <joint name="metal_leg_mirror_joint" type="fixed">
    <parent link="rot_bracket_link"/>
    <child link="metal_leg_mirror_link"/>
    <origin rpy="0 0 0.5235987755982988" xyz="-0.08227 -0.0475 0"/>
  </joint>
  <link name="bjw_link">
    <visual>
      <geometry>
        <cylinder length="0.03" radius="0.0109"/>
      </geometry>
      <origin rpy="0 0 0" xyz="0 0 0"/>
    </visual>
  </link>
  <joint name="bjw_joint" type="revolute">
    <parent link="metal_leg_mirror_link"/>
    <child link="bjw_link"/>
    <origin rpy="0 0 0" xyz="-0.0291 0 0"/>
    <limit effort="10" lower="-1.57" upper="1.57" velocity="3"/>
  </joint>
  <link name="short_leg_link">
    <visual>
      <geometry>
        <box rpy="0 0 0" size="0.09490000000000001 0.0218 0.0218"/>
      </geometry>
      <material name="steel">
        <color rgba="0.5 0.5 0.5 1"/>
        <!-- Adjust the RGBA values for your desired color and opacity -->
      </material>
      <origin rpy="0 0 0" xyz="0 0 0"/>
    </visual>
  </link>
  <joint name="short_leg_joint" type="fixed">
    <parent link="bjw_link"/>
    <child link="short_leg_link"/>
    <origin rpy="0 0 0" xyz="-0.047450000000000006 0 0"/>
  </joint>
  <link name="short_leg_two_link">
    <visual>
      <geometry>
        <box rpy="0 0 0" size="0.09490000000000001 0.0218 0.0218"/>
      </geometry>
      <origin rpy="0 0 0" xyz="0.047450000000000006 0 0"/>
      <material name="steel">
        <color rgba="0.5 0.5 0.5 1"/>
        <!-- Adjust the RGBA values for your desired color and opacity -->
      </material>
    </visual>
  </link>
  <joint name="short_leg_two_joint" type="fixed">
    <parent link="bjw_link"/>
    <child link="short_leg_two_link"/>
    <origin rpy="0 0 -1.0471975511965976" xyz="0 0 0"/>
  </joint>
  <link name="wheel_one">
    <visual>
      <geometry>
        <cylinder length="0.03" radius="0.03"/>
      </geometry>
      <origin rpy="0 0 0" xyz="0 0 0"/>
      <material name="steel">
        <color rgba="0.4 0.7 0.8 1"/>
        <!-- Adjust the RGBA values for your desired color and opacity -->
      </material>
    </visual>
  </link>
  <joint name="wheel_one_joint" type="revolute">
    <parent link="metal_leg_link"/>
    <child link="wheel_one"/>
    <origin rpy="0 0 0" xyz="0.082 0 -0.0259"/>
    <limit effort="10" lower="-1.57" upper="1.57" velocity="3"/>
  </joint>
  <link name="wheel_two">
    <visual>
      <geometry>
        <cylinder length="0.03" radius="0.03"/>
      </geometry>
      <origin rpy="0 0 0" xyz="0 0 0"/>
      <material name="steel">
        <color rgba="0.4 0.7 0.8 1"/>
        <!-- Adjust the RGBA values for your desired color and opacity -->
      </material>
    </visual>
  </link>
  <joint name="wheel_two_joint" type="revolute">
    <parent link="short_leg_two_link"/>
    <child link="wheel_two"/>
    <origin rpy="0 0 0" xyz="0.09490000000000001 0 -0.0259"/>
    <limit effort="10" lower="-1.57" upper="1.57" velocity="3"/>
  </joint>
  <link name="wheel_three">
    <visual>
      <geometry>
        <cylinder length="0.03" radius="0.03"/>
      </geometry>
      <origin rpy="0 0 0" xyz="0 0 0"/>
      <material name="steel">
        <color rgba="0.4 0.7 0.8 1"/>
        <!-- Adjust the RGBA values for your desired color and opacity -->
      </material>
    </visual>
  </link>
  <joint name="wheel_three_joint" type="revolute">
    <parent link="short_leg_link"/>
    <child link="wheel_three"/>
    <origin rpy="0 0 0" xyz="-0.047450000000000006 0 -0.0259"/>
    <limit effort="10" lower="-1.57" upper="1.57" velocity="3"/>
  </joint>
</robot>
