<?xml version="1.0" ?>
<!-- =================================================================================== -->
<!-- |    This document was autogenerated by xacro from dc_xacro.xacro                 | -->
<!-- |    EDITING THIS FILE BY HAND IS NOT RECOMMENDED                                 | -->
<!-- =================================================================================== -->
<robot name="minesweeper">
  <link name="link"/>
  <!--Central platform-->
  <link name="base_link">
    <visual>
      <geometry>
        <box size="0.328 0.0127 0.105"/>
      </geometry>
      <origin xyz="0 0 0.0525"/>
    </visual>
    <collision>
      <geometry>
        <box size="0.328 0.0127 0.105"/>
      </geometry>
      <origin xyz="0 0 0.0525"/>
    </collision>
    <visual>
      <geometry>
        <box size="0.328 0.0457 0.0127"/>
      </geometry>
      <origin xyz="0 0.0165 0.11134999999999999"/>
    </visual>
    <collision>
      <geometry>
        <box size="0.328 0.0457 0.0127"/>
      </geometry>
      <origin xyz="0 0.0165 0.11134999999999999"/>
    </collision>
    <visual>
      <geometry>
        <box size="0.328 0.0457 0.0127"/>
      </geometry>
      <origin xyz="0 0.0165 -0.00635"/>
    </visual>
    <collision>
      <geometry>
        <box size="0.328 0.0457 0.0127"/>
      </geometry>
      <origin xyz="0 0.0165 -0.00635"/>
    </collision>
    <inertial>
      <origin rpy="0 0 0" xyz="0.328 0.0127 0.105"/>
      <!-- Position and orientation of the inertia frame relative to the link frame -->
      <mass value="0.67"/>
      <!-- Mass of the link in kilograms -->
      <inertia ixx="0.0006245678583333333" ixy="0" ixz="0" iyy="0.006622335833333334" iyz="0" izz="0.006015778691666667"/>
      <!-- Inertia tensor components in kg*m**2 -->
    </inertial>
  </link>
  <joint name="base_joint" type="fixed">
    <parent link="link"/>
    <child link="base_link"/>
    <origin xyz="0 0 0.175"/>
    <!-- 0.1 just for visualization-->
  </joint>
  <!-- Component Plate-->
  <link name="component_plate_link">
    <visual>
      <geometry>
        <box size="0.3279 0.254 0.005"/>
      </geometry>
      <origin xyz="0 0 0"/>
      <material name="translucent_glass">
        <color rgba="0.8 0.8 0.8 0.5"/>
        <!-- Adjust the RGBA values for your desired color and opacity -->
      </material>
    </visual>
    <collision>
      <geometry>
        <box size="0.3279 0.254 0.005"/>
      </geometry>
      <origin xyz="0 0 0"/>
    </collision>
    <inertial>
      <origin rpy="0 0 0" xyz="$0 0 0"/>
      <!-- Position and orientation of the inertia frame relative to the link frame -->
      <mass value="0.55"/>
      <!-- Mass of the link in kilograms -->
      <inertia ixx="0.002958129166666667" ixy="0" ixz="0" iyy="0.004929072958333335" iyz="0" izz="0.007884910458333335"/>
      <!-- Inertia tensor components in kg*m**2 -->
    </inertial>
    <visual>
      <geometry>
        <cylinder length="0.254" radius="0.01"/>
      </geometry>
      <origin rpy="1.5707963267948966 0 0" xyz="0 0 0.0525"/>
      <material name="steel">
        <color rgba="0.5 0.5 0.5 1"/>
        <!-- Adjust the RGBA values for your desired color and opacity -->
      </material>
    </visual>
    <collision>
      <geometry>
        <cylinder length="0.254" radius="0.01"/>
      </geometry>
      <origin rpy="1.5707963267948966 0 0" xyz="0 0 0.0525"/>
    </collision>
    <inertial>
      <origin rpy="0 0 0" xyz="$0 0 0.0525"/>
      <!-- Position and orientation of the inertia frame relative to the link frame -->
      <mass value="0.8"/>
      <!-- Mass of the link in kilograms -->
      <inertia ixx="0.0043210666666666665" ixy="0" ixz="0" iyy="0.0043210666666666665" iyz="0" izz="4e-05"/>
      <!-- Inertia tensor components in kg*m**2 -->
    </inertial>
  </link>
  <joint name="component_plate_joint" type="fixed">
    <parent link="base_link"/>
    <child link="component_plate_link"/>
    <origin xyz="0 0.13335 0.0025"/>
  </joint>
  <!-- ELEC BOX -->
  <link name="elec_box_link">
    <visual>
      <geometry>
        <box size="0.08 0.08 0.04"/>
      </geometry>
      <origin xyz="0 0 0"/>
      <material name="steel">
        <color rgba="0 0 0 1"/>
        <!-- Adjust the RGBA values for your desired color and opacity -->
      </material>
    </visual>
    <collision>
      <geometry>
        <box size="0.08 0.08 0.04"/>
      </geometry>
      <origin xyz="0 0 0"/>
    </collision>
    <inertial>
      <origin rpy="0 0 0" xyz="0 0 0"/>
      <!-- Position and orientation of the inertia frame relative to the link frame -->
      <mass value="1.0"/>
      <!-- Mass of the link in kilograms -->
      <inertia ixx="0.0006666666666666666" ixy="0" ixz="0" iyy="0.0006666666666666666" iyz="0" izz="0.0010666666666666667"/>
      <!-- Inertia tensor components in kg*m**2 -->
    </inertial>
  </link>
  <joint name="elec_box_joint" type="fixed">
    <parent link="component_plate_link"/>
    <child link="elec_box_link"/>
    <origin xyz="0 0 0.0225"/>
  </joint>
  <!-- MIRROR OF THE ABOVE -->
  <link name="mirror_base_link">
    <visual>
      <geometry>
        <box size="0.328 0.0127 0.105"/>
      </geometry>
      <origin xyz="0 0 0.0525"/>
    </visual>
    <collision>
      <geometry>
        <box size="0.328 0.0127 0.105"/>
      </geometry>
      <origin xyz="0 0 0.0525"/>
    </collision>
    <visual>
      <geometry>
        <box size="0.328 0.0457 0.0127"/>
      </geometry>
      <origin xyz="0 -0.0165 0.11134999999999999"/>
    </visual>
    <collision>
      <geometry>
        <box size="0.328 0.0457 0.0127"/>
      </geometry>
      <origin xyz="0 -0.0165 0.11134999999999999"/>
    </collision>
    <visual>
      <geometry>
        <box size="0.328 0.0457 0.0127"/>
      </geometry>
      <origin xyz="0 -0.0165 -0.00635"/>
    </visual>
    <collision>
      <geometry>
        <box size="0.328 0.0457 0.0127"/>
      </geometry>
      <origin xyz="0 -0.0165 -0.00635"/>
    </collision>
    <inertial>
      <origin rpy="0 0 0" xyz="0 0 0.0525"/>
      <!-- Position and orientation of the inertia frame relative to the link frame -->
      <mass value="0.67"/>
      <!-- Mass of the link in kilograms -->
      <inertia ixx="0.0006245678583333333" ixy="0" ixz="0" iyy="0.006622335833333334" iyz="0" izz="0.006015778691666667"/>
      <!-- Inertia tensor components in kg*m**2 -->
    </inertial>
  </link>
  <joint name="mirror_base_joint" type="fixed">
    <parent link="base_link"/>
    <child link="mirror_base_link"/>
    <origin xyz="0 0.2667 0"/>
  </joint>
  <!-- Left Side Structure -->
  <link name="left_base_link"/>
  <link name="circular_plate_link">
    <visual>
      <geometry>
        <cylinder length="0.005" radius="0.0375"/>
      </geometry>
      <origin rpy="1.5707963267948966 0 0" xyz="0 0 0"/>
    </visual>
    <collision>
      <geometry>
        <cylinder length="0.005" radius="0.0375"/>
      </geometry>
      <origin rpy="1.5707963267948966 0 0" xyz="0 0 0"/>
    </collision>
    <inertial>
      <origin rpy="1.5707963267948966 0 0" xyz="0 0 0"/>
      <!-- Position and orientation of the inertia frame relative to the link frame -->
      <mass value="0.01"/>
      <!-- Mass of the link in kilograms -->
      <inertia ixx="3.536458333333333e-06" ixy="0" ixz="0" iyy="3.536458333333333e-06" iyz="0" izz="7.03125e-06"/>
      <!-- Inertia tensor components in kg*m^2 -->
    </inertial>
  </link>
  <joint name="circular_plate_joint" type="fixed">
    <parent link="left_base_link"/>
    <child link="circular_plate_link"/>
  </joint>
  <link name="bracket_link">
    <visual>
      <geometry>
        <cylinder length="0.045" radius="0.02"/>
      </geometry>
      <origin rpy="0 0 0" xyz="0 0 0"/>
    </visual>
    <collision>
      <geometry>
        <cylinder length="0.045" radius="0.02"/>
      </geometry>
      <origin rpy="0 0 0" xyz="0 0 0"/>
    </collision>
    <inertial>
      <origin rpy="0 0 0" xyz="0 0 0"/>
      <!-- Position and orientation of the inertia frame relative to the link frame -->
      <mass value="0.03"/>
      <!-- Mass of the link in kilograms -->
      <inertia ixx="2.6874999999999997e-06" ixy="0" ixz="0" iyy="2.6874999999999997e-06" iyz="0" izz="2.0000000000000003e-06"/>
      <!-- Inertia tensor components in kg*m^2 -->
    </inertial>
  </link>
  <joint name="bracket_joint" type="fixed">
    <parent link="left_base_link"/>
    <child link="bracket_link"/>
    <origin rpy="1.5707963267948966 0 0" xyz="0 0.024999999999999998 0"/>
  </joint>
  <link name="rot_bracket_link">
    <visual>
      <geometry>
        <cylinder length="0.045" radius="0.03"/>
      </geometry>
      <origin rpy="0 0 0" xyz="0 0 0"/>
    </visual>
    <collision>
      <geometry>
        <cylinder length="0.045" radius="0.03"/>
      </geometry>
      <origin rpy="0 0 0" xyz="0 0 0"/>
    </collision>
    <inertial>
      <origin rpy="0 0 0" xyz="0 0 0"/>
      <!-- Position and orientation of the inertia frame relative to the link frame -->
      <mass value="0.07"/>
      <!-- Mass of the link in kilograms -->
      <inertia ixx="2.7562500000000002e-05" ixy="0" ixz="0" iyy="2.7562500000000002e-05" iyz="0" izz="3.15e-05"/>
      <!-- Inertia tensor components in kg*m^2 -->
    </inertial>
    <visual>
      <geometry>
        <box size="0.05 0.035 0.035"/>
      </geometry>
      <origin rpy="0 0 -0.5235987755982988" xyz="0.025 -0.0175 0"/>
    </visual>
    <collision>
      <geometry>
        <box size="0.05 0.035 0.035"/>
      </geometry>
      <origin rpy="0 0 -0.5235987755982988" xyz="0.025 -0.0175 0"/>
    </collision>
    <visual>
      <geometry>
        <box size="0.05 0.035 0.035"/>
      </geometry>
      <origin rpy="0 0 0.5235987755982988" xyz="-0.025 -0.0175 0"/>
    </visual>
    <collision>
      <geometry>
        <box size="0.05 0.035 0.035"/>
      </geometry>
      <origin rpy="0 0 0.5235987755982988" xyz="-0.025 -0.0175 0"/>
    </collision>
  </link>
  <joint name="rot_bracket_joint" type="fixed">
    <parent link="bracket_link"/>
    <child link="rot_bracket_link"/>
    <origin rpy="0 0 0" xyz="0 0 -0.045"/>
  </joint>
  <link name="metal_leg_link">
    <visual>
      <geometry>
        <box size="0.25 0.025 0.025"/>
      </geometry>
      <origin rpy="0 0 0" xyz="0 0 0"/>
      <material name="steel">
        <color rgba="0.5 0.5 0.5 1"/>
        <!-- Adjust the RGBA values for your desired color and opacity -->
      </material>
    </visual>
    <collision>
      <geometry>
        <box size="0.25 0.025 0.025"/>
      </geometry>
      <origin rpy="0 0 0" xyz="0 0 0"/>
    </collision>
    <inertial>
      <origin rpy="0 0 0" xyz="0 0 0"/>
      <!-- Position and orientation of the inertia frame relative to the link frame -->
      <mass value="1.4"/>
      <!-- Mass of the link in kilograms -->
      <inertia ixx="0.00014583333333333335" ixy="0" ixz="0" iyy="0.007364583333333332" iyz="0" izz="0.007364583333333332"/>
      <!-- Inertia tensor components in kg*m^2 -->
    </inertial>
  </link>
  <joint name="metal_leg_joint" type="fixed">
    <parent link="rot_bracket_link"/>
    <child link="metal_leg_link"/>
    <origin rpy="0 0 -0.5235987755982988" xyz="0.15588 -0.09 0"/>
  </joint>
  <link name="metal_leg_mirror_link">
    <visual>
      <geometry>
        <box size="0.1 0.025 0.025"/>
      </geometry>
      <origin rpy="0 0 0" xyz="0 0 0"/>
      <material name="steel">
        <color rgba="0.5 0.5 0.5 1"/>
        <!-- Adjust the RGBA values for your desired color and opacity -->
      </material>
    </visual>
    <collision>
      <geometry>
        <box size="0.1 0.025 0.025"/>
      </geometry>
      <origin rpy="0 0 0" xyz="0 0 0"/>
    </collision>
    <inertial>
      <origin rpy="0 0 0" xyz="0 0 0"/>
      <!-- Position and orientation of the inertia frame relative to the link frame -->
      <mass value="0.1"/>
      <!-- Mass of the link in kilograms -->
      <inertia ixx="1.0416666666666668e-05" ixy="0" ixz="0" iyy="8.854166666666669e-05" iyz="0" izz="8.854166666666669e-05"/>
      <!-- Inertia tensor components in kg*m^2 -->
    </inertial>
  </link>
  <joint name="metal_leg_mirror_joint" type="fixed">
    <parent link="rot_bracket_link"/>
    <child link="metal_leg_mirror_link"/>
    <origin rpy="0 0 0.5235987755982988" xyz="-0.09093000000000001 -0.052500000000000005 0"/>
  </joint>
  <link name="bjw_link">
    <visual>
      <geometry>
        <cylinder length="0.03" radius="0.01"/>
      </geometry>
      <origin rpy="0 0 0" xyz="0 0 0"/>
    </visual>
    <collision>
      <geometry>
        <cylinder length="0.03" radius="0.01"/>
      </geometry>
      <origin rpy="0 0 0" xyz="0 0 0"/>
    </collision>
    <inertial>
      <origin rpy="0 0 0" xyz="0 0 0"/>
      <!-- Position and orientation of the inertia frame relative to the link frame -->
      <mass value="0.03"/>
      <!-- Mass of the link in kilograms -->
      <inertia ixx="2.9999999999999997e-06" ixy="0" ixz="0" iyy="2.9999999999999997e-06" iyz="0" izz="1.5e-06"/>
      <!-- Inertia tensor components in kg*m^2 -->
    </inertial>
  </link>
  <joint name="bjw_joint" type="revolute">
    <parent link="metal_leg_mirror_link"/>
    <child link="bjw_link"/>
    <origin rpy="0 0 0" xyz="-0.04 0 0"/>
    <limit effort="10" lower="-2" upper="0" velocity="3"/>
    <axis xyz="0 0 1"/>
  </joint>
  <link name="short_leg_link">
    <visual>
      <geometry>
        <box rpy="0 0 0" size="0.16 0.025 0.025"/>
      </geometry>
      <material name="steel">
        <color rgba="0.5 0.5 0.5 1"/>
        <!-- Adjust the RGBA values for your desired color and opacity -->
      </material>
      <origin rpy="0 0 0" xyz="0 0 0"/>
    </visual>
    <collision>
      <geometry>
        <box rpy="0 0 0" size="0.16 0.025 0.025"/>
      </geometry>
      <origin rpy="0 0 0" xyz="0 0 0"/>
    </collision>
    <inertial>
      <origin rpy="0 0 0" xyz="0 0 0"/>
      <!-- Position and orientation of the inertia frame relative to the link frame -->
      <mass value="0.05"/>
      <!-- Mass of the link in kilograms -->
      <inertia ixx="5.208333333333334e-06" ixy="0" ixz="0" iyy="0.00010927083333333334" iyz="0" izz="0.00010927083333333334"/>
      <!-- Inertia tensor components in kg*m^2 -->
    </inertial>
  </link>
  <joint name="short_leg_joint" type="fixed">
    <parent link="bjw_link"/>
    <child link="short_leg_link"/>
    <origin rpy="0 0 0" xyz="-0.08 0 0"/>
  </joint>
  <link name="short_leg_two_link">
    <visual>
      <geometry>
        <box rpy="0 0 0" size="0.16 0.025 0.025"/>
      </geometry>
      <origin rpy="0 0 0" xyz="0.08 0 0"/>
      <material name="steel">
        <color rgba="0.5 0.5 0.5 1"/>
        <!-- Adjust the RGBA values for your desired color and opacity -->
      </material>
    </visual>
    <collision>
      <geometry>
        <box rpy="0 0 0" size="0.16 0.025 0.025"/>
      </geometry>
      <origin rpy="0 0 0" xyz="0.08 0 0"/>
    </collision>
    <inertial>
      <origin rpy="0 0 0" xyz="0.08 0 0"/>
      <!-- Position and orientation of the inertia frame relative to the link frame -->
      <mass value="0.05"/>
      <!-- Mass of the link in kilograms -->
      <inertia ixx="5.208333333333334e-06" ixy="0" ixz="0" iyy="0.00010927083333333334" iyz="0" izz="0.00010927083333333334"/>
      <!-- Inertia tensor components in kg*m^2 -->
    </inertial>
  </link>
  <joint name="short_leg_two_joint" type="fixed">
    <parent link="bjw_link"/>
    <child link="short_leg_two_link"/>
    <origin rpy="0 0 -1.0471975511965976" xyz="0 0 0"/>
  </joint>
  <link name="wheel_one">
    <visual>
      <geometry>
        <cylinder length="0.065" radius="0.075"/>
      </geometry>
      <origin rpy="0 0 0" xyz="0 0 0"/>
      <material name="steel">
        <color rgba="0.4 0.7 0.8 1"/>
        <!-- Adjust the RGBA values for your desired color and opacity -->
      </material>
    </visual>
    <collision>
      <geometry>
        <cylinder length="0.065" radius="0.075"/>
      </geometry>
      <origin rpy="0 0 0" xyz="0 0 0"/>
    </collision>
    <inertial>
      <origin rpy="0 0 0" xyz="0 0 0"/>
      <!-- Position and orientation of the inertia frame relative to the link frame -->
      <mass value="0.05"/>
      <!-- Mass of the link in kilograms -->
      <inertia ixx="0.0008791666666666667" ixy="0" ixz="0" iyy="0.0008791666666666667" iyz="0" izz="0.00140625"/>
      <!-- Inertia tensor components in kg*m^2 -->
    </inertial>
  </link>
  <joint name="wheel_one_joint" type="continuous">
    <parent link="metal_leg_link"/>
    <child link="wheel_one"/>
    <origin rpy="0 0 0" xyz="0.125 0 -0.045"/>
    <axis xyz="0 0 1"/>
  </joint>
  <link name="wheel_two">
    <visual>
      <geometry>
        <cylinder length="0.065" radius="0.075"/>
      </geometry>
      <origin rpy="0 0 0" xyz="0 0 0"/>
      <material name="steel">
        <color rgba="0.4 0.7 0.8 1"/>
        <!-- Adjust the RGBA values for your desired color and opacity -->
      </material>
    </visual>
    <collision>
      <geometry>
        <cylinder length="0.065" radius="0.075"/>
      </geometry>
      <origin rpy="0 0 0" xyz="0 0 0"/>
    </collision>
    <inertial>
      <origin rpy="0 0 0" xyz="0 0 0"/>
      <!-- Position and orientation of the inertia frame relative to the link frame -->
      <mass value="0.05"/>
      <!-- Mass of the link in kilograms -->
      <inertia ixx="0.0008791666666666667" ixy="0" ixz="0" iyy="0.0008791666666666667" iyz="0" izz="0.00140625"/>
      <!-- Inertia tensor components in kg*m^2 -->
    </inertial>
  </link>
  <joint name="wheel_two_joint" type="continuous">
    <parent link="short_leg_two_link"/>
    <child link="wheel_two"/>
    <origin rpy="0 0 0" xyz="0.16 0 -0.045"/>
    <axis xyz="0 0 1"/>
  </joint>
  <link name="wheel_three">
    <visual>
      <geometry>
        <cylinder length="0.065" radius="0.075"/>
      </geometry>
      <origin rpy="0 0 0" xyz="0 0 0"/>
      <material name="steel">
        <color rgba="0.4 0.7 0.8 1"/>
        <!-- Adjust the RGBA values for your desired color and opacity -->
      </material>
    </visual>
    <collision>
      <geometry>
        <cylinder length="0.065" radius="0.075"/>
      </geometry>
      <origin rpy="0 0 0" xyz="0 0 0"/>
    </collision>
    <inertial>
      <origin rpy="0 0 0" xyz="0 0 0"/>
      <!-- Position and orientation of the inertia frame relative to the link frame -->
      <mass value="0.05"/>
      <!-- Mass of the link in kilograms -->
      <inertia ixx="0.0008791666666666667" ixy="0" ixz="0" iyy="0.0008791666666666667" iyz="0" izz="0.00140625"/>
      <!-- Inertia tensor components in kg*m^2 -->
    </inertial>
  </link>
  <joint name="wheel_three_joint" type="continuous">
    <parent link="short_leg_link"/>
    <child link="wheel_three"/>
    <origin rpy="0 0 0" xyz="-0.08 0 -0.045"/>
    <axis xyz="0 0 1"/>
  </joint>
  <joint name="left_xacro_joint" type="fixed">
    <parent link="mirror_base_link"/>
    <child link="left_base_link"/>
    <!-- Assuming there's a link in left_xacro.xacro named base_link_left_xacro -->
    <origin xyz="0 0.00635 0.0525"/>
    <!-- Adjust the origin as needed -->
  </joint>
  <!-- Right Side Structure -->
  <link name="right_base_link"/>
  <link name="r_circular_plate_link">
    <visual>
      <geometry>
        <cylinder length="0.005" radius="0.0375"/>
      </geometry>
      <origin rpy="1.5707963267948966 0 0" xyz="0 0 0"/>
    </visual>
    <collision>
      <geometry>
        <cylinder length="0.005" radius="0.0375"/>
      </geometry>
      <origin rpy="1.5707963267948966 0 0" xyz="0 0 0"/>
    </collision>
    <inertial>
      <origin rpy="1.5707963267948966 0 0" xyz="0 0 0"/>
      <!-- Position and orientation of the inertia frame relative to the link frame -->
      <mass value="0.01"/>
      <!-- Mass of the link in kilograms -->
      <inertia ixx="3.536458333333333e-06" ixy="0" ixz="0" iyy="3.536458333333333e-06" iyz="0" izz="7.03125e-06"/>
      <!-- Inertia tensor components in kg*m^2 -->
    </inertial>
  </link>
  <joint name="r_circular_plate_joint" type="fixed">
    <parent link="right_base_link"/>
    <child link="r_circular_plate_link"/>
  </joint>
  <link name="r_bracket_link">
    <visual>
      <geometry>
        <cylinder length="0.045" radius="0.02"/>
      </geometry>
      <origin rpy="0 0 0" xyz="0 0 0"/>
    </visual>
    <collision>
      <geometry>
        <cylinder length="0.045" radius="0.02"/>
      </geometry>
      <origin rpy="0 0 0" xyz="0 0 0"/>
    </collision>
    <inertial>
      <origin rpy="0 0 0" xyz="0 0 0"/>
      <!-- Position and orientation of the inertia frame relative to the link frame -->
      <mass value="0.03"/>
      <!-- Mass of the link in kilograms -->
      <inertia ixx="2.6874999999999997e-06" ixy="0" ixz="0" iyy="2.6874999999999997e-06" iyz="0" izz="2.0000000000000003e-06"/>
      <!-- Inertia tensor components in kg*m^2 -->
    </inertial>
  </link>
  <joint name="r_bracket_joint" type="fixed">
    <parent link="r_circular_plate_link"/>
    <child link="r_bracket_link"/>
    <origin rpy="1.5707963267948966 0 0" xyz="0 -0.024999999999999998 0"/>
  </joint>
  <link name="r_rot_bracket_link">
    <visual>
      <geometry>
        <cylinder length="0.045" radius="0.03"/>
      </geometry>
      <origin rpy="0 0 0" xyz="0 0 0"/>
    </visual>
    <collision>
      <geometry>
        <cylinder length="0.045" radius="0.03"/>
      </geometry>
      <origin rpy="0 0 0" xyz="0 0 0"/>
    </collision>
    <inertial>
      <origin rpy="0 0 0" xyz="0 0 0"/>
      <!-- Position and orientation of the inertia frame relative to the link frame -->
      <mass value="0.07"/>
      <!-- Mass of the link in kilograms -->
      <inertia ixx="2.7562500000000002e-05" ixy="0" ixz="0" iyy="2.7562500000000002e-05" iyz="0" izz="3.15e-05"/>
      <!-- Inertia tensor components in kg*m^2 -->
    </inertial>
    <visual>
      <geometry>
        <box size="0.06 0.035 0.035"/>
      </geometry>
      <origin rpy="0 0 -0.5235987755982988" xyz="0.03 -0.0175 0"/>
    </visual>
    <collision>
      <geometry>
        <box size="0.06 0.035 0.035"/>
      </geometry>
      <origin rpy="0 0 -0.5235987755982988" xyz="0.03 -0.0175 0"/>
    </collision>
    <visual>
      <geometry>
        <box size="0.06 0.035 0.035"/>
      </geometry>
      <origin rpy="0 0 0.5235987755982988" xyz="-0.03 -0.0175 0"/>
    </visual>
    <collision>
      <geometry>
        <box size="0.06 0.035 0.035"/>
      </geometry>
      <origin rpy="0 0 0.5235987755982988" xyz="-0.03 -0.0175 0"/>
    </collision>
  </link>
  <joint name="r_rot_bracket_joint" type="fixed">
    <parent link="r_bracket_link"/>
    <child link="r_rot_bracket_link"/>
    <origin rpy="0 0 0" xyz="0 0 0.045"/>
    <limit effort="10" lower="-1.57" upper="1.57" velocity="3"/>
  </joint>
  <link name="r_metal_leg_link">
    <visual>
      <geometry>
        <box size="0.25 0.025 0.025"/>
      </geometry>
      <origin rpy="0 0 0" xyz="0 0 0"/>
      <material name="steel">
        <color rgba="0.5 0.5 0.5 1"/>
        <!-- Adjust the RGBA values for your desired color and opacity -->
      </material>
    </visual>
    <collision>
      <geometry>
        <box size="0.25 0.025 0.025"/>
      </geometry>
      <origin rpy="0 0 0" xyz="0 0 0"/>
    </collision>
    <inertial>
      <origin rpy="0 0 0" xyz="0 0 0"/>
      <!-- Position and orientation of the inertia frame relative to the link frame -->
      <mass value="1.4"/>
      <!-- Mass of the link in kilograms -->
      <inertia ixx="0.00014583333333333335" ixy="0" ixz="0" iyy="0.007364583333333332" iyz="0" izz="0.007364583333333332"/>
      <!-- Inertia tensor components in kg*m^2 -->
    </inertial>
  </link>
  <joint name="r_metal_leg_joint" type="fixed">
    <parent link="r_rot_bracket_link"/>
    <child link="r_metal_leg_link"/>
    <origin rpy="0 0 -0.5235987755982988" xyz="0.15588 -0.09 0"/>
  </joint>
  <link name="r_metal_leg_mirror_link">
    <visual>
      <geometry>
        <box size="0.1 0.025 0.025"/>
      </geometry>
      <origin rpy="0 0 0" xyz="0 0 0"/>
      <material name="steel">
        <color rgba="0.5 0.5 0.5 1"/>
        <!-- Adjust the RGBA values for your desired color and opacity -->
      </material>
    </visual>
    <collision>
      <geometry>
        <box size="0.1 0.025 0.025"/>
      </geometry>
      <origin rpy="0 0 0" xyz="0 0 0"/>
    </collision>
    <inertial>
      <origin rpy="0 0 0" xyz="0 0 0"/>
      <!-- Position and orientation of the inertia frame relative to the link frame -->
      <mass value="0.1"/>
      <!-- Mass of the link in kilograms -->
      <inertia ixx="1.0416666666666668e-05" ixy="0" ixz="0" iyy="8.854166666666669e-05" iyz="0" izz="8.854166666666669e-05"/>
      <!-- Inertia tensor components in kg*m^2 -->
    </inertial>
  </link>
  <joint name="r_metal_leg_mirror_joint" type="fixed">
    <parent link="r_rot_bracket_link"/>
    <child link="r_metal_leg_mirror_link"/>
    <origin rpy="0 0 0.5235987755982988" xyz="-0.09093000000000001 -0.052500000000000005 0"/>
  </joint>
  <link name="r_bjw_link">
    <visual>
      <geometry>
        <cylinder length="0.03" radius="0.01"/>
      </geometry>
      <origin rpy="0 0 0" xyz="0 0 0"/>
    </visual>
    <collision>
      <geometry>
        <cylinder length="0.03" radius="0.01"/>
      </geometry>
      <origin rpy="0 0 0" xyz="0 0 0"/>
    </collision>
    <inertial>
      <origin rpy="0 0 0" xyz="0 0 0"/>
      <!-- Position and orientation of the inertia frame relative to the link frame -->
      <mass value="0.03"/>
      <!-- Mass of the link in kilograms -->
      <inertia ixx="2.9999999999999997e-06" ixy="0" ixz="0" iyy="2.9999999999999997e-06" iyz="0" izz="1.5e-06"/>
      <!-- Inertia tensor components in kg*m^2 -->
    </inertial>
  </link>
  <joint name="r_bjw_joint" type="revolute">
    <parent link="r_metal_leg_mirror_link"/>
    <child link="r_bjw_link"/>
    <origin rpy="0 0 0" xyz="-0.04 0 0"/>
    <limit effort="10" lower="-2" upper="0" velocity="3"/>
    <axis xyz="0 0 1"/>
  </joint>
  <link name="r_short_leg_link">
    <visual>
      <geometry>
        <box rpy="0 0 0" size="0.16 0.025 0.025"/>
      </geometry>
      <material name="steel">
        <color rgba="0.5 0.5 0.5 1"/>
        <!-- Adjust the RGBA values for your desired color and opacity -->
      </material>
      <origin rpy="0 0 0" xyz="0 0 0"/>
    </visual>
    <collision>
      <geometry>
        <box rpy="0 0 0" size="0.16 0.025 0.025"/>
      </geometry>
      <origin rpy="0 0 0" xyz="0 0 0"/>
    </collision>
    <inertial>
      <origin rpy="0 0 0" xyz="0 0 0"/>
      <!-- Position and orientation of the inertia frame relative to the link frame -->
      <mass value="0.05"/>
      <!-- Mass of the link in kilograms -->
      <inertia ixx="5.208333333333334e-06" ixy="0" ixz="0" iyy="0.00010927083333333334" iyz="0" izz="0.00010927083333333334"/>
      <!-- Inertia tensor components in kg*m^2 -->
    </inertial>
  </link>
  <joint name="r_short_leg_joint" type="fixed">
    <parent link="r_bjw_link"/>
    <child link="r_short_leg_link"/>
    <origin rpy="0 0 0" xyz="-0.08 0 0"/>
  </joint>
  <link name="r_short_leg_two_link">
    <visual>
      <geometry>
        <box rpy="0 0 0" size="0.16 0.025 0.025"/>
      </geometry>
      <origin rpy="0 0 0" xyz="0.08 0 0"/>
      <material name="steel">
        <color rgba="0.5 0.5 0.5 1"/>
        <!-- Adjust the RGBA values for your desired color and opacity -->
      </material>
    </visual>
    <collision>
      <geometry>
        <box rpy="0 0 0" size="0.16 0.025 0.025"/>
      </geometry>
      <origin rpy="0 0 0" xyz="0.08 0 0"/>
    </collision>
    <inertial>
      <origin rpy="0 0 0" xyz="0.08 0 0"/>
      <!-- Position and orientation of the inertia frame relative to the link frame -->
      <mass value="0.05"/>
      <!-- Mass of the link in kilograms -->
      <inertia ixx="5.208333333333334e-06" ixy="0" ixz="0" iyy="0.00010927083333333334" iyz="0" izz="0.00010927083333333334"/>
      <!-- Inertia tensor components in kg*m^2 -->
    </inertial>
  </link>
  <joint name="r_short_leg_two_joint" type="fixed">
    <parent link="r_bjw_link"/>
    <child link="r_short_leg_two_link"/>
    <origin rpy="0 0 -1.0471975511965976" xyz="0 0 0"/>
  </joint>
  <link name="r_wheel_one">
    <visual>
      <geometry>
        <cylinder length="0.065" radius="0.075"/>
      </geometry>
      <origin rpy="0 0 0" xyz="0 0 0"/>
      <material name="steel">
        <color rgba="0.4 0.7 0.8 1"/>
        <!-- Adjust the RGBA values for your desired color and opacity -->
      </material>
    </visual>
    <collision>
      <geometry>
        <cylinder length="0.065" radius="0.075"/>
      </geometry>
      <origin rpy="0 0 0" xyz="0 0 0"/>
    </collision>
    <inertial>
      <origin rpy="0 0 0" xyz="0 0 0"/>
      <!-- Position and orientation of the inertia frame relative to the link frame -->
      <mass value="0.5"/>
      <!-- Mass of the link in kilograms -->
      <inertia ixx="0.0008791666666666667" ixy="0" ixz="0" iyy="0.0008791666666666667" iyz="0" izz="0.00140625"/>
      <!-- Inertia tensor components in kg*m^2 -->
    </inertial>
  </link>
  <joint name="r_wheel_one_joint" type="continuous">
    <parent link="r_metal_leg_link"/>
    <child link="r_wheel_one"/>
    <origin rpy="0 0 0" xyz="0.125 0 0.045"/>
    <axis xyz="0 0 1"/>
  </joint>
  <link name="r_wheel_two">
    <visual>
      <geometry>
        <cylinder length="0.065" radius="0.075"/>
      </geometry>
      <origin rpy="0 0 0" xyz="0 0 0"/>
      <material name="steel">
        <color rgba="0.4 0.7 0.8 1"/>
        <!-- Adjust the RGBA values for your desired color and opacity -->
      </material>
    </visual>
    <collision>
      <geometry>
        <cylinder length="0.065" radius="0.075"/>
      </geometry>
      <origin rpy="0 0 0" xyz="0 0 0"/>
    </collision>
    <inertial>
      <origin rpy="0 0 0" xyz="0 0 0"/>
      <!-- Position and orientation of the inertia frame relative to the link frame -->
      <mass value="0.5"/>
      <!-- Mass of the link in kilograms -->
      <inertia ixx="0.0008791666666666667" ixy="0" ixz="0" iyy="0.0008791666666666667" iyz="0" izz="0.00140625"/>
      <!-- Inertia tensor components in kg*m^2 -->
    </inertial>
  </link>
  <joint name="r_wheel_two_joint" type="continuous">
    <parent link="r_short_leg_two_link"/>
    <child link="r_wheel_two"/>
    <origin rpy="0 0 0" xyz="0.16 0 0.045"/>
    <axis xyz="0  0 1"/>
  </joint>
  <link name="r_wheel_three">
    <visual>
      <geometry>
        <cylinder length="0.065" radius="0.075"/>
      </geometry>
      <origin rpy="0 0 0" xyz="0 0 0"/>
      <material name="steel">
        <color rgba="0.4 0.7 0.8 1"/>
        <!-- Adjust the RGBA values for your desired color and opacity -->
      </material>
    </visual>
    <collision>
      <geometry>
        <cylinder length="0.065" radius="0.075"/>
      </geometry>
      <origin rpy="0 0 0" xyz="0 0 0"/>
    </collision>
    <inertial>
      <origin rpy="0 0 0" xyz="0 0 0"/>
      <!-- Position and orientation of the inertia frame relative to the link frame -->
      <mass value="0.5"/>
      <!-- Mass of the link in kilograms -->
      <inertia ixx="0.0008791666666666667" ixy="0" ixz="0" iyy="0.0008791666666666667" iyz="0" izz="0.00140625"/>
      <!-- Inertia tensor components in kg*m^2 -->
    </inertial>
  </link>
  <joint name="r_wheel_three_joint" type="continuous">
    <parent link="r_short_leg_link"/>
    <child link="r_wheel_three"/>
    <origin rpy="0 0 0" xyz="-0.08 0 0.045"/>
    <axis xyz="0 0 1"/>
  </joint>
  <joint name="right_xacro_joint" type="fixed">
    <parent link="mirror_base_link"/>
    <child link="right_base_link"/>
    <!-- Assuming there's a link in left_xacro.xacro named base_link_left_xacro -->
    <origin xyz="0 -0.27305 0.0525"/>
    <!-- Adjust the origin as needed -->
  </joint>
  <!-- DETECTOR -->
  <link name="detector_link">
    <visual>
      <geometry>
        <box size="0.35 0.0165 0.0165"/>
      </geometry>
      <origin xyz="0 0 0"/>
      <material name="steel">
        <color rgba="0 0 1 1"/>
        <!-- Adjust the RGBA values for your desired color and opacity -->
      </material>
    </visual>
    <collision>
      <geometry>
        <box size="0.35 0.0165 0.0165"/>
      </geometry>
      <origin xyz="0 0 0"/>
    </collision>
    <inertial>
      <origin rpy="0 0 0" xyz="0 0 0"/>
      <!-- Position and orientation of the inertia frame relative to the link frame -->
      <mass value="0.1"/>
      <!-- Mass of the link in kilograms -->
      <inertia ixx="4.5375e-06" ixy="0" ixz="0" iyy="0.0010231020833333332" iyz="0" izz="0.0010231020833333332"/>
      <!-- Inertia tensor components in kg*m**2 -->
    </inertial>
    <visual>
      <geometry>
        <box size="0.0165 0.4 0.0165"/>
      </geometry>
      <origin xyz="0.18325 0.13335 0"/>
      <material name="steel">
        <color rgba="0 0 1 1"/>
        <!-- Adjust the RGBA values for your desired color and opacity -->
      </material>
    </visual>
    <collision>
      <geometry>
        <box size="0.0165 0.4 0.0165"/>
      </geometry>
      <origin xyz="0.18325 0.13335 0"/>
    </collision>
    <inertial>
      <origin rpy="0 0 0" xyz="0.18325 0.13335 0"/>
      <!-- Position and orientation of the inertia frame relative to the link frame -->
      <mass value="0.1"/>
      <!-- Mass of the link in kilograms -->
      <inertia ixx="0.0013356020833333337" ixy="0" ixz="0" iyy="4.5375e-06" iyz="0" izz="0.0013356020833333337"/>
      <!-- Inertia tensor components in kg*m**2 -->
    </inertial>
    <visual>
      <geometry>
        <box size="0.35 0.0165 0.0165"/>
      </geometry>
      <origin xyz="0 0.254 0"/>
      <material name="steel">
        <color rgba="0 0 1 1"/>
        <!-- Adjust the RGBA values for your desired color and opacity -->
      </material>
    </visual>
    <collision>
      <geometry>
        <box size="0.35 0.0165 0.0165"/>
      </geometry>
      <origin xyz="0 0.254 0"/>
    </collision>
    <inertial>
      <origin rpy="0 0 0" xyz="0 0.254 0"/>
      <!-- Position and orientation of the inertia frame relative to the link frame -->
      <mass value="0.1"/>
      <!-- Mass of the link in kilograms -->
      <inertia ixx="4.5375e-06" ixy="0" ixz="0" iyy="0.0010231020833333332" iyz="0" izz="0.0010231020833333332"/>
      <!-- Inertia tensor components in kg*m**2 -->
    </inertial>
  </link>
  <joint name="detector_joint" type="fixed">
    <parent link="base_link"/>
    <child link="detector_link"/>
    <origin xyz="0.06100000000000001 0 -0.02095 "/>
  </joint>
</robot>
