<?xml version="1.0" ?>
<!-- =================================================================================== -->
<!-- |    This document was autogenerated by xacro from main_xacro.xacro               | -->
<!-- |    EDITING THIS FILE BY HAND IS NOT RECOMMENDED                                 | -->
<!-- =================================================================================== -->
<robot name="minesweeper">
  <link name="link"/>
  <link name="base_link">
    <visual>
      <geometry>
        <box size="0.15 0.01 0.05"/>
      </geometry>
      <origin xyz="0 0 0.025"/>
    </visual>
    <visual>
      <geometry>
        <box size="0.15 0.04 0.01"/>
      </geometry>
      <origin xyz="0 0.015 0.055"/>
    </visual>
    <visual>
      <geometry>
        <box size="0.15 0.04 0.01"/>
      </geometry>
      <origin xyz="0 0.015 -0.005"/>
    </visual>
  </link>
  <joint name="base_joint" type="fixed">
    <parent link="link"/>
    <child link="base_link"/>
    <origin xyz="0 0 0.1"/>
    <!-- 0.1 just for visualization-->
  </joint>
  <link name="component_plate_link">
    <visual>
      <geometry>
        <box size="0.15 0.15 0.005"/>
      </geometry>
      <origin xyz="0 0 0"/>
      <material name="translucent_glass">
        <color rgba="0.8 0.8 0.8 0.5"/>
        <!-- Adjust the RGBA values for your desired color and opacity -->
      </material>
    </visual>
    <visual>
      <geometry>
        <cylinder length="0.15" radius="0.01"/>
      </geometry>
      <origin rpy="1.5707963267948966 0 0" xyz="0 0 0.025"/>
      <material name="steel">
        <color rgba="0.5 0.5 0.5 1"/>
        <!-- Adjust the RGBA values for your desired color and opacity -->
      </material>
    </visual>
  </link>
  <joint name="component_plate_joint" type="fixed">
    <parent link="base_link"/>
    <child link="component_plate_link"/>
    <origin xyz="0 0.08 0.0025"/>
  </joint>
  <link name="mirror_base_link">
    <visual>
      <geometry>
        <box size="0.15 0.01 0.05"/>
      </geometry>
      <origin xyz="0 0 0.025"/>
    </visual>
    <visual>
      <geometry>
        <box size="0.15 0.04 0.01"/>
      </geometry>
      <origin xyz="0 -0.015 0.055"/>
    </visual>
    <visual>
      <geometry>
        <box size="0.15 0.04 0.01"/>
      </geometry>
      <origin xyz="0 -0.015 -0.005"/>
    </visual>
  </link>
  <joint name="mirror_base_joint" type="fixed">
    <parent link="base_link"/>
    <child link="mirror_base_link"/>
    <origin xyz="0 0.16 0"/>
  </joint>
  <link name="left_base_link"/>
  <link name="circular_plate_link">
    <visual>
      <geometry>
        <cylinder length="0.0005" radius="0.03"/>
      </geometry>
      <origin rpy="1.5707963267948966 0 0" xyz="0 0 0"/>
    </visual>
    <visual>
      <geometry>
        <cylinder length="0.1" radius="0.015"/>
      </geometry>
      <origin rpy="1.5707963267948966 0 0" xyz="0 0.0505 0"/>
    </visual>
  </link>
  <joint name="circular_plate_joint" type="fixed">
    <parent link="left_base_link"/>
    <child link="circular_plate_link"/>
  </joint>
  <link name="bracket_link">
    <visual>
      <geometry>
        <cylinder length="0.04" radius="0.02"/>
      </geometry>
      <origin rpy="0 0 0" xyz="0 0 0"/>
    </visual>
  </link>
  <joint name="bracket_joint" type="fixed">
    <parent link="circular_plate_link"/>
    <child link="bracket_link"/>
    <origin rpy="1.5707963267948966 0 0" xyz="0 0.05025 0"/>
  </joint>
  <link name="rot_bracket_link">
    <visual>
      <geometry>
        <cylinder length="0.04" radius="0.02"/>
      </geometry>
      <origin rpy="0 0 0" xyz="0 0 0"/>
    </visual>
    <visual>
      <geometry>
        <box size="0.056 0.0279 0.0254"/>
      </geometry>
      <origin rpy="0 0 -0.5235987755982988" xyz="0.028 -0.01395 0"/>
    </visual>
    <visual>
      <geometry>
        <box size="0.056 0.0279 0.0254"/>
      </geometry>
      <origin rpy="0 0 0.5235987755982988" xyz="-0.028 -0.01395 0"/>
    </visual>
  </link>
  <joint name="rot_bracket_joint" type="revolute">
    <parent link="bracket_link"/>
    <child link="rot_bracket_link"/>
    <origin rpy="0 0 0" xyz="0 0 -0.04"/>
    <limit effort="10" lower="-1.57" upper="1.57" velocity="3"/>
  </joint>
  <link name="metal_leg_link">
    <visual>
      <geometry>
        <box size="0.164 0.0218 0.0218"/>
      </geometry>
      <origin rpy="0 0 0" xyz="0 0 0"/>
    </visual>
  </link>
  <joint name="metal_leg_joint" type="fixed">
    <parent link="rot_bracket_link"/>
    <child link="metal_leg_link"/>
    <origin rpy="0 0 -0.5235987755982988" xyz="0.12124000000000001 -0.07 0"/>
  </joint>
  <link name="metal_leg_mirror_link">
    <visual>
      <geometry>
        <box size="0.08 0.0218 0.0218"/>
      </geometry>
      <origin rpy="0 0 0" xyz="0 0 0"/>
    </visual>
  </link>
  <joint name="metal_leg_mirror_joint" type="fixed">
    <parent link="rot_bracket_link"/>
    <child link="metal_leg_mirror_link"/>
    <origin rpy="0 0 0.5235987755982988" xyz="-0.084868 -0.049 0"/>
  </joint>
  <link name="bjw_link">
    <visual>
      <geometry>
        <cylinder length="0.03" radius="0.0109"/>
      </geometry>
      <origin rpy="0 0 0" xyz="0 0 0"/>
    </visual>
  </link>
  <joint name="bjw_joint" type="revolute">
    <parent link="metal_leg_mirror_link"/>
    <child link="bjw_link"/>
    <origin rpy="0 0 0" xyz="-0.0291 0 -0.0259"/>
    <limit effort="10" lower="-1.57" upper="1.57" velocity="3"/>
  </joint>
  <link name="short_leg_link">
    <visual>
      <geometry>
        <box rpy="0 0 0" size="0.09490000000000001 0.0218 0.0218"/>
      </geometry>
      <origin rpy="0 0 0" xyz="0 0 0"/>
    </visual>
  </link>
  <joint name="short_leg_joint" type="fixed">
    <parent link="bjw_link"/>
    <child link="short_leg_link"/>
    <origin rpy="0 0 0" xyz="-0.047450000000000006 0 0"/>
  </joint>
  <link name="short_leg_two_link">
    <visual>
      <geometry>
        <box rpy="0 0 0" size="0.09490000000000001 0.0218 0.0218"/>
      </geometry>
      <origin rpy="0 0 0" xyz="0.047450000000000006 0 0"/>
    </visual>
  </link>
  <joint name="short_leg_two_joint" type="fixed">
    <parent link="bjw_link"/>
    <child link="short_leg_two_link"/>
    <origin rpy="0 0 -1.0471975511965976" xyz="0 0 0"/>
  </joint>
  <link name="wheel_one">
    <visual>
      <geometry>
        <cylinder length="0.03" radius="0.03"/>
      </geometry>
      <origin rpy="0 0 0" xyz="0 0 0"/>
    </visual>
  </link>
  <joint name="wheel_one_joint" type="revolute">
    <parent link="metal_leg_link"/>
    <child link="wheel_one"/>
    <origin rpy="0 0 0" xyz="0.082 0 -0.0259"/>
    <limit effort="10" lower="-1.57" upper="1.57" velocity="3"/>
  </joint>
  <link name="wheel_two">
    <visual>
      <geometry>
        <cylinder length="0.03" radius="0.03"/>
      </geometry>
      <origin rpy="0 0 0" xyz="0 0 0"/>
    </visual>
  </link>
  <joint name="wheel_two_joint" type="revolute">
    <parent link="short_leg_two_link"/>
    <child link="wheel_two"/>
    <origin rpy="0 0 0" xyz="0.09490000000000001 0 -0.0259"/>
    <limit effort="10" lower="-1.57" upper="1.57" velocity="3"/>
  </joint>
  <link name="wheel_three">
    <visual>
      <geometry>
        <cylinder length="0.03" radius="0.03"/>
      </geometry>
      <origin rpy="0 0 0" xyz="0 0 0"/>
    </visual>
  </link>
  <joint name="wheel_three_joint" type="revolute">
    <parent link="short_leg_link"/>
    <child link="wheel_three"/>
    <origin rpy="0 0 0" xyz="-0.047450000000000006 0 -0.0259"/>
    <limit effort="10" lower="-1.57" upper="1.57" velocity="3"/>
  </joint>
  <joint name="left_xacro_joint" type="fixed">
    <parent link="mirror_base_link"/>
    <child link="circular_plate_link"/>
    <!-- Assuming there's a link in left_xacro.xacro named base_link_left_xacro -->
    <origin xyz="0 0.005 0.025"/>
    <!-- Adjust the origin as needed -->
  </joint>
  <link name="right_base_link"/>
  <link name="r_circular_plate_link">
    <visual>
      <geometry>
        <cylinder length="0.0005" radius="0.03"/>
      </geometry>
      <origin rpy="1.5707963267948966 0 0" xyz="0 0 0"/>
    </visual>
    <visual>
      <geometry>
        <cylinder length="0.1" radius="0.015"/>
      </geometry>
      <origin rpy="1.5707963267948966 0 0" xyz="0 -0.0505 0"/>
    </visual>
  </link>
  <joint name="r_circular_plate_joint" type="fixed">
    <parent link="right_base_link"/>
    <child link="r_circular_plate_link"/>
  </joint>
  <link name="r_bracket_link">
    <visual>
      <geometry>
        <cylinder length="0.04" radius="0.02"/>
      </geometry>
      <origin rpy="0 0 0" xyz="0 0 0"/>
    </visual>
  </link>
  <joint name="r_bracket_joint" type="fixed">
    <parent link="r_circular_plate_link"/>
    <child link="r_bracket_link"/>
    <origin rpy="1.5707963267948966 0 0" xyz="0 -0.05025 0"/>
  </joint>
  <link name="r_rot_bracket_link">
    <visual>
      <geometry>
        <cylinder length="0.04" radius="0.02"/>
      </geometry>
      <origin rpy="0 0 0" xyz="0 0 0"/>
    </visual>
    <visual>
      <geometry>
        <box size="0.056 0.0279 0.0254"/>
      </geometry>
      <origin rpy="0 0 -0.5235987755982988" xyz="0.028 -0.01395 0"/>
    </visual>
    <visual>
      <geometry>
        <box size="0.056 0.0279 0.0254"/>
      </geometry>
      <origin rpy="0 0 0.5235987755982988" xyz="-0.028 -0.01395 0"/>
    </visual>
  </link>
  <joint name="r_rot_bracket_joint" type="revolute">
    <parent link="r_bracket_link"/>
    <child link="r_rot_bracket_link"/>
    <origin rpy="0 0 0" xyz="0 0 0.04"/>
    <limit effort="10" lower="-1.57" upper="1.57" velocity="3"/>
  </joint>
  <link name="r_metal_leg_link">
    <visual>
      <geometry>
        <box size="0.164 0.0218 0.0218"/>
      </geometry>
      <origin rpy="0 0 0" xyz="0 0 0"/>
    </visual>
  </link>
  <joint name="r_metal_leg_joint" type="fixed">
    <parent link="r_rot_bracket_link"/>
    <child link="r_metal_leg_link"/>
    <origin rpy="0 0 -0.5235987755982988" xyz="0.12124000000000001 -0.07 0"/>
  </joint>
  <link name="r_metal_leg_mirror_link">
    <visual>
      <geometry>
        <box size="0.08 0.0218 0.0218"/>
      </geometry>
      <origin rpy="0 0 0" xyz="0 0 0"/>
    </visual>
  </link>
  <joint name="r_metal_leg_mirror_joint" type="fixed">
    <parent link="r_rot_bracket_link"/>
    <child link="r_metal_leg_mirror_link"/>
    <origin rpy="0 0 0.5235987755982988" xyz="-0.084868 -0.049 0"/>
  </joint>
  <link name="r_bjw_link">
    <visual>
      <geometry>
        <cylinder length="0.03" radius="0.0109"/>
      </geometry>
      <origin rpy="0 0 0" xyz="0 0 0"/>
    </visual>
  </link>
  <joint name="r_bjw_joint" type="revolute">
    <parent link="r_metal_leg_mirror_link"/>
    <child link="r_bjw_link"/>
    <origin rpy="0 0 0" xyz="-0.0291 0 0.0259"/>
    <limit effort="10" lower="-1.57" upper="1.57" velocity="3"/>
  </joint>
  <link name="r_short_leg_link">
    <visual>
      <geometry>
        <box rpy="0 0 0" size="0.09490000000000001 0.0218 0.0218"/>
      </geometry>
      <origin rpy="0 0 0" xyz="0 0 0"/>
    </visual>
  </link>
  <joint name="r_short_leg_joint" type="fixed">
    <parent link="r_bjw_link"/>
    <child link="r_short_leg_link"/>
    <origin rpy="0 0 0" xyz="-0.047450000000000006 0 0"/>
  </joint>
  <link name="r_short_leg_two_link">
    <visual>
      <geometry>
        <box rpy="0 0 0" size="0.09490000000000001 0.0218 0.0218"/>
      </geometry>
      <origin rpy="0 0 0" xyz="0.047450000000000006 0 0"/>
    </visual>
  </link>
  <joint name="r_short_leg_two_joint" type="fixed">
    <parent link="r_bjw_link"/>
    <child link="r_short_leg_two_link"/>
    <origin rpy="0 0 -1.0471975511965976" xyz="0 0 0"/>
  </joint>
  <link name="r_wheel_one">
    <visual>
      <geometry>
        <cylinder length="0.03" radius="0.03"/>
      </geometry>
      <origin rpy="0 0 0" xyz="0 0 0"/>
    </visual>
  </link>
  <joint name="r_wheel_one_joint" type="revolute">
    <parent link="r_metal_leg_link"/>
    <child link="r_wheel_one"/>
    <origin rpy="0 0 0" xyz="0.082 0 0.0259"/>
    <limit effort="10" lower="-1.57" upper="1.57" velocity="3"/>
  </joint>
  <link name="r_wheel_two">
    <visual>
      <geometry>
        <cylinder length="0.03" radius="0.03"/>
      </geometry>
      <origin rpy="0 0 0" xyz="0 0 0"/>
    </visual>
  </link>
  <joint name="r_wheel_two_joint" type="revolute">
    <parent link="r_short_leg_two_link"/>
    <child link="r_wheel_two"/>
    <origin rpy="0 0 0" xyz="0.09490000000000001 0 0.0259"/>
    <limit effort="10" lower="-1.57" upper="1.57" velocity="3"/>
  </joint>
  <link name="r_wheel_three">
    <visual>
      <geometry>
        <cylinder length="0.03" radius="0.03"/>
      </geometry>
      <origin rpy="0 0 0" xyz="0 0 0"/>
    </visual>
  </link>
  <joint name="r_wheel_three_joint" type="revolute">
    <parent link="r_short_leg_link"/>
    <child link="r_wheel_three"/>
    <origin rpy="0 0 0" xyz="-0.047450000000000006 0 0.0259"/>
    <limit effort="10" lower="-1.57" upper="1.57" velocity="3"/>
  </joint>
  <joint name="right_xacro_joint" type="fixed">
    <parent link="base_link"/>
    <child link="r_circular_plate_link"/>
    <origin xyz="0 -0.005 0.025"/>
  </joint>
</robot>
