<?xml version="1.0" ?>
<!-- =================================================================================== -->
<!-- |    This document was autogenerated by xacro from right_xacro.xacro              | -->
<!-- |    EDITING THIS FILE BY HAND IS NOT RECOMMENDED                                 | -->
<!-- =================================================================================== -->
<!-- Content in right_xacro.xacro -->
<robot name="minesweeper_right">
  <link name="right_base_link"/>
  <link name="r_circular_plate_link">
    <visual>
      <geometry>
        <cylinder length="0.0005" radius="0.03"/>
      </geometry>
      <origin rpy="1.5707963267948966 0 0" xyz="0 0 0"/>
    </visual>
    <visual>
      <geometry>
        <cylinder length="0.1" radius="0.015"/>
      </geometry>
      <origin rpy="1.5707963267948966 0 0" xyz="0 -0.0505 0"/>
    </visual>
  </link>
  <joint name="r_circular_plate_joint" type="fixed">
    <parent link="right_base_link"/>
    <child link="r_circular_plate_link"/>
  </joint>
  <link name="r_bracket_link">
    <visual>
      <geometry>
        <cylinder length="0.04" radius="0.02"/>
      </geometry>
      <origin rpy="0 0 0" xyz="0 0 0"/>
    </visual>
  </link>
  <joint name="r_bracket_joint" type="fixed">
    <parent link="r_circular_plate_link"/>
    <child link="r_bracket_link"/>
    <origin rpy="1.5707963267948966 0 0" xyz="0 -0.05025 0"/>
  </joint>
  <link name="r_rot_bracket_link">
    <visual>
      <geometry>
        <cylinder length="0.04" radius="0.02"/>
      </geometry>
      <origin rpy="0 0 0" xyz="0 0 0"/>
    </visual>
    <visual>
      <geometry>
        <box size="0.056 0.0279 0.0254"/>
      </geometry>
      <origin rpy="0 0 -0.5235987755982988" xyz="0.028 -0.01395 0"/>
    </visual>
    <visual>
      <geometry>
        <box size="0.056 0.0279 0.0254"/>
      </geometry>
      <origin rpy="0 0 0.5235987755982988" xyz="-0.028 -0.01395 0"/>
    </visual>
  </link>
  <joint name="r_rot_bracket_joint" type="revolute">
    <parent link="r_bracket_link"/>
    <child link="r_rot_bracket_link"/>
    <origin rpy="0 0 0" xyz="0 0 0.04"/>
    <limit effort="10" lower="-1.57" upper="1.57" velocity="3"/>
  </joint>
  <link name="r_metal_leg_link">
    <visual>
      <geometry>
        <box size="0.164 0.0218 0.0218"/>
      </geometry>
      <origin rpy="0 0 0" xyz="0 0 0"/>
    </visual>
  </link>
  <joint name="r_metal_leg_joint" type="fixed">
    <parent link="r_rot_bracket_link"/>
    <child link="r_metal_leg_link"/>
    <origin rpy="0 0 -0.5235987755982988" xyz="0.12124000000000001 -0.07 0"/>
  </joint>
  <link name="r_metal_leg_mirror_link">
    <visual>
      <geometry>
        <box size="0.08 0.0218 0.0218"/>
      </geometry>
      <origin rpy="0 0 0" xyz="0 0 0"/>
    </visual>
  </link>
  <joint name="r_metal_leg_mirror_joint" type="fixed">
    <parent link="r_rot_bracket_link"/>
    <child link="r_metal_leg_mirror_link"/>
    <origin rpy="0 0 0.5235987755982988" xyz="-0.084868 -0.049 0"/>
  </joint>
  <link name="r_bjw_link">
    <visual>
      <geometry>
        <cylinder length="0.03" radius="0.0109"/>
      </geometry>
      <origin rpy="0 0 0" xyz="0 0 0"/>
    </visual>
  </link>
  <joint name="r_bjw_joint" type="revolute">
    <parent link="r_metal_leg_mirror_link"/>
    <child link="r_bjw_link"/>
    <origin rpy="0 0 0" xyz="-0.0291 0 0.0259"/>
    <limit effort="10" lower="-1.57" upper="1.57" velocity="3"/>
  </joint>
  <link name="r_short_leg_link">
    <visual>
      <geometry>
        <box rpy="0 0 0" size="0.09490000000000001 0.0218 0.0218"/>
      </geometry>
      <origin rpy="0 0 0" xyz="0 0 0"/>
    </visual>
  </link>
  <joint name="r_short_leg_joint" type="fixed">
    <parent link="r_bjw_link"/>
    <child link="r_short_leg_link"/>
    <origin rpy="0 0 0" xyz="-0.047450000000000006 0 0"/>
  </joint>
  <link name="r_short_leg_two_link">
    <visual>
      <geometry>
        <box rpy="0 0 0" size="0.09490000000000001 0.0218 0.0218"/>
      </geometry>
      <origin rpy="0 0 0" xyz="0.047450000000000006 0 0"/>
    </visual>
  </link>
  <joint name="r_short_leg_two_joint" type="fixed">
    <parent link="r_bjw_link"/>
    <child link="r_short_leg_two_link"/>
    <origin rpy="0 0 -1.0471975511965976" xyz="0 0 0"/>
  </joint>
  <link name="r_wheel_one">
    <visual>
      <geometry>
        <cylinder length="0.03" radius="0.03"/>
      </geometry>
      <origin rpy="0 0 0" xyz="0 0 0"/>
    </visual>
  </link>
  <joint name="r_wheel_one_joint" type="revolute">
    <parent link="r_metal_leg_link"/>
    <child link="r_wheel_one"/>
    <origin rpy="0 0 0" xyz="0.082 0 0.0259"/>
    <limit effort="10" lower="-1.57" upper="1.57" velocity="3"/>
  </joint>
  <link name="r_wheel_two">
    <visual>
      <geometry>
        <cylinder length="0.03" radius="0.03"/>
      </geometry>
      <origin rpy="0 0 0" xyz="0 0 0"/>
    </visual>
  </link>
  <joint name="r_wheel_two_joint" type="revolute">
    <parent link="r_short_leg_two_link"/>
    <child link="r_wheel_two"/>
    <origin rpy="0 0 0" xyz="0.09490000000000001 0 0.0259"/>
    <limit effort="10" lower="-1.57" upper="1.57" velocity="3"/>
  </joint>
  <link name="r_wheel_three">
    <visual>
      <geometry>
        <cylinder length="0.03" radius="0.03"/>
      </geometry>
      <origin rpy="0 0 0" xyz="0 0 0"/>
    </visual>
  </link>
  <joint name="r_wheel_three_joint" type="revolute">
    <parent link="r_short_leg_link"/>
    <child link="r_wheel_three"/>
    <origin rpy="0 0 0" xyz="-0.047450000000000006 0 0.0259"/>
    <limit effort="10" lower="-1.57" upper="1.57" velocity="3"/>
  </joint>
</robot>
